Workbook

Sheet Summary
A1: H&R Block (NYSE: HRB) - Leveraged Buyout Analysis
A2: Take-private LBO, 5-year hold, exit end of FY2031. $ in millions. Live links to the model (Scenario switch on Assumptions!B3).
A4: Entry EV / EBITDA | B4: ='LBO Model'!B12 -> 8
A5: Implied offer price / premium | B5: ='LBO Model'!B14 -> 60.80947
A6: Premium to $44.05 | B6: ='LBO Model'!B15 -> 0.3804647
A7: Enterprise value | B7: ='LBO Model'!B13 -> 8241.008
A8: Total debt / EBITDA at close | B8: =Assumptions!B15 -> 5
A9: Debt financing % of total cap | B9: =1-'LBO Model'!B16 -> 0.58573891
A10: Sponsor equity | B10: ='LBO Model'!B7 -> 3642.7589
A11: Exit multiple | B11: =Assumptions!B33 -> 8
A12: MOIC | B12: ='LBO Model'!B65 -> 2.242121
A13: IRR | B13: ='LBO Model'!B66 -> 0.17525419
A14: Debt / EBITDA at exit | B14: ='LBO Model'!G54 -> 1.8690896
A16: Recommendation
A17: PASS at 8.0x (38% premium): base-case IRR of 17.5% is below a typical 20% sponsor hurdle, and the downside case (growth stalls, margin compresses, exit 6.5x) returns only about 1.0x. PROCEED at or below 7.5x EV/EBITDA (about a 29% premium), where base IRR is about 21% at an 8.0x exit. Debt capacity is adequate: EBITDA / interest stays above 2.2x even in the downside, and leverage falls from 5.0x to 1.9x by FY2031 in the base case. Key risks: seasonal tax-prep business, DIY competition, and sensitivity to the exit multiple.

Sheet Assumptions
A1: H&R Block (HRB) - LBO Assumptions ($ in millions, except per share)
A2: Blue = input. Scenario 1 = Base, 2 = Downside. Market data as of Oct 9, 2026 close; FY ends June 30.
A3: Scenario (1=Base, 2=Downside) | B3: 1
A5: TRANSACTION
A6: LTM Adj. EBITDA (FY2026) | B6: 1030.126
A7: Entry EV / EBITDA | B7: 8
A8: Existing debt (refinanced) | B8: 1491.493
A9: Existing cash | B9: 958.706
A10: Current share price ($) | B10: 44.05
A11: Shares outstanding (mm) = mkt cap / price | B11: =5583.787118/B10 -> 126.76021
A12: Minimum cash retained | B12: 300
A14: FINANCING
A15: Total leverage (x EBITDA) | B15: 5
A16: Term Loan B (x EBITDA) | B16: 3
A17: Senior Notes (x EBITDA) | B17: =B15-MIN(B16,B15) -> 2
A18: Term Loan B rate | B18: 0.08
A19: Senior Notes rate | B19: 0.095
A20: TLB mandatory amortization (% of original) | B20: 0.01
A21: Cash sweep (% of excess FCF) | B21: 1
A22: Transaction fees (% of EV) | B22: 0.015
A23: Financing fees (% of new debt) | B23: 0.025
A24: Financing fee amortization (years) | B24: 7
A25: Tax rate | B25: 0.24
A27: OPERATING / EXIT
A28: D&A (% revenue) | B28: 0.031
A29: Capex (% revenue) | B29: 0.021
A30: Change in NWC (% of change in revenue) | B30: 0.05
A31: Exit EV / EBITDA - Base | B31: 8
A32: Exit EV / EBITDA - Downside | B32: 6.5
A33: Exit multiple used | B33: =CHOOSE(B3,B31,B32) -> 8
A34: FY2026 revenue | B34: 3945.392
A36: Operating cases | B36: FY2027E | C36: FY2028E | D36: FY2029E | E36: FY2030E | F36: FY2031E
A37: Revenue growth - Base | B37: 0.045 | C37: 0.045 | D37: 0.045 | E37: 0.045 | F37: 0.045
A38: EBITDA margin - Base | B38: 0.261 | C38: 0.261 | D38: 0.261 | E38: 0.261 | F38: 0.261
A39: Revenue growth - Downside | B39: 0.01 | C39: 0 | D39: 0 | E39: 0.02 | F39: 0.02
A40: EBITDA margin - Downside | B40: 0.245 | C40: 0.235 | D40: 0.235 | E40: 0.24 | F40: 0.24
A42: Notes: Base growth (4.5%) is just above HRB's FY23-FY26 revenue CAGR of 4.3%; base margin holds the FY26 level (26.1%). Rates, leverage and fees are my assumptions, not quotes. Interest is computed on beginning-of-year balances (no circularity).

Sheet LBO Model
A1: H&R Block - LBO Model ($ in millions)
A3: Sources & Uses | D3: Uses
A4: Term Loan B | B4: =Assumptions!B16*Assumptions!B6 -> 3090.378 | D4: Purchase of equity | E4: =B13-Assumptions!B8+Assumptions!B9 -> 7708.221
A5: Senior Notes | B5: =Assumptions!B17*Assumptions!B6 -> 2060.252 | D5: Refinance existing debt | E5: =Assumptions!B8 -> 1491.493
A6: Balance sheet cash used | B6: =Assumptions!B9-Assumptions!B12 -> 658.706 | D6: Transaction fees | E6: =Assumptions!B22*B13 -> 123.61512
A7: Sponsor equity (plug) | B7: =E8-B4-B5-B6 -> 3642.7589 | D7: Financing fees | E7: =Assumptions!B23*(B4+B5) -> 128.76575
A8: Total sources | B8: =SUM(B4:B7) -> 9452.0949 | D8: Total uses | E8: =SUM(E4:E7) -> 9452.0949
A10: Entry valuation | D10: Check: sources - uses | E10: =ROUND(B8-E8,6) -> 0
A11: LTM EBITDA | B11: =Assumptions!B6 -> 1030.126
A12: Entry multiple | B12: =Assumptions!B7 -> 8
A13: Enterprise value | B13: =B11*B12 -> 8241.008
A14: Implied offer price / share ($) | B14: =E4/Assumptions!B11 -> 60.80947
A15: Premium to current price | B15: =B14/Assumptions!B10-1 -> 0.3804647
A16: Sponsor equity % of total capitalization | B16: =B7/(B7+B4+B5) -> 0.41426109
A19: Income statement | B19: FY2026A | C19: FY2027E | D19: FY2028E | E19: FY2029E | F19: FY2030E | G19: FY2031E
A20: Revenue | B20: =Assumptions!B34 -> 3945.392 | C20: =B20*(1+C21) -> 4122.9346 | D20: =C20*(1+D21) -> 4308.4667 | E20: =D20*(1+E21) -> 4502.3477 | F20: =E20*(1+F21) -> 4704.9533 | G20: =F20*(1+G21) -> 4916.6762
A21: growth % | C21: =CHOOSE(Assumptions!$B$3,Assumptions!B37,Assumptions!B39) -> 0.045 | D21: =CHOOSE(Assumptions!$B$3,Assumptions!C37,Assumptions!C39) -> 0.045 | E21: =CHOOSE(Assumptions!$B$3,Assumptions!D37,Assumptions!D39) -> 0.045 | F21: =CHOOSE(Assumptions!$B$3,Assumptions!E37,Assumptions!E39) -> 0.045 | G21: =CHOOSE(Assumptions!$B$3,Assumptions!F37,Assumptions!F39) -> 0.045
A22: EBITDA | B22: =Assumptions!B6 -> 1030.126 | C22: =C20*C23 -> 1076.0859 | D22: =D20*D23 -> 1124.5098 | E22: =E20*E23 -> 1175.1127 | F22: =F20*F23 -> 1227.9928 | G22: =G20*G23 -> 1283.2525
A23: margin % | B23: =B22/B20 -> 0.26109598 | C23: =CHOOSE(Assumptions!$B$3,Assumptions!B38,Assumptions!B40) -> 0.261 | D23: =CHOOSE(Assumptions!$B$3,Assumptions!C38,Assumptions!C40) -> 0.261 | E23: =CHOOSE(Assumptions!$B$3,Assumptions!D38,Assumptions!D40) -> 0.261 | F23: =CHOOSE(Assumptions!$B$3,Assumptions!E38,Assumptions!E40) -> 0.261 | G23: =CHOOSE(Assumptions!$B$3,Assumptions!F38,Assumptions!F40) -> 0.261
A24: D&A | C24: =C20*Assumptions!$B$28 -> 127.81097 | D24: =D20*Assumptions!$B$28 -> 133.56247 | E24: =E20*Assumptions!$B$28 -> 139.57278 | F24: =F20*Assumptions!$B$28 -> 145.85355 | G24: =G20*Assumptions!$B$28 -> 152.41696
A25: EBIT | C25: =C22-C24 -> 948.27497 | D25: =D22-D24 -> 990.94734 | E25: =E22-E24 -> 1035.54 | F25: =F22-F24 -> 1082.1393 | G25: =G22-G24 -> 1130.8355
A26: Interest - Term Loan B | C26: =B46*Assumptions!$B$18 -> 247.23024 | D26: =C46*Assumptions!$B$18 -> 213.56537 | E26: =D46*Assumptions!$B$18 -> 175.14273 | F26: =E46*Assumptions!$B$18 -> 131.55106 | G26: =F46*Assumptions!$B$18 -> 82.348583
A27: Interest - Senior Notes | C27: =B50*Assumptions!$B$19 -> 195.72394 | D27: =C50*Assumptions!$B$19 -> 195.72394 | E27: =D50*Assumptions!$B$19 -> 195.72394 | F27: =E50*Assumptions!$B$19 -> 195.72394 | G27: =F50*Assumptions!$B$19 -> 195.72394
A28: Financing fee amortization | C28: =$E$7/Assumptions!$B$24 -> 18.395107 | D28: =$E$7/Assumptions!$B$24 -> 18.395107 | E28: =$E$7/Assumptions!$B$24 -> 18.395107 | F28: =$E$7/Assumptions!$B$24 -> 18.395107 | G28: =$E$7/Assumptions!$B$24 -> 18.395107
A29: Pre-tax income | C29: =C25-C26-C27-C28 -> 486.92568 | D29: =D25-D26-D27-D28 -> 563.26292 | E29: =E25-E26-E27-E28 -> 646.27819 | F29: =F25-F26-F27-F28 -> 736.46917 | G29: =G25-G26-G27-G28 -> 834.36791
A30: Taxes | C30: =MAX(0,C29*Assumptions!$B$25) -> 116.86216 | D30: =MAX(0,D29*Assumptions!$B$25) -> 135.1831 | E30: =MAX(0,E29*Assumptions!$B$25) -> 155.10677 | F30: =MAX(0,F29*Assumptions!$B$25) -> 176.7526 | G30: =MAX(0,G29*Assumptions!$B$25) -> 200.2483
A31: Net income | C31: =C29-C30 -> 370.06352 | D31: =D29-D30 -> 428.07982 | E31: =E29-E30 -> 491.17142 | F31: =F29-F30 -> 559.71657 | G31: =G29-G30 -> 634.11961
A33: Cash flow & debt paydown | C33: FY2027E | D33: FY2028E | E33: FY2029E | F33: FY2030E | G33: FY2031E
A34: EBITDA | C34: =C22 -> 1076.0859 | D34: =D22 -> 1124.5098 | E34: =E22 -> 1175.1127 | F34: =F22 -> 1227.9928 | G34: =G22 -> 1283.2525
A35: Less: cash interest | C35: =-(C26+C27) -> -442.95418 | D35: =-(D26+D27) -> -409.28931 | E35: =-(E26+E27) -> -370.86667 | F35: =-(F26+F27) -> -327.275 | G35: =-(G26+G27) -> -278.07252
A36: Less: taxes | C36: =-C30 -> -116.86216 | D36: =-D30 -> -135.1831 | E36: =-E30 -> -155.10677 | F36: =-F30 -> -176.7526 | G36: =-G30 -> -200.2483
A37: Less: capex | C37: =-C20*Assumptions!$B$29 -> -86.581627 | D37: =-D20*Assumptions!$B$29 -> -90.477801 | E37: =-E20*Assumptions!$B$29 -> -94.549302 | F37: =-F20*Assumptions!$B$29 -> -98.80402 | G37: =-G20*Assumptions!$B$29 -> -103.2502
A38: Less: increase in NWC | C38: =-(C20-B20)*Assumptions!$B$30 -> -8.877132 | D38: =-(D20-C20)*Assumptions!$B$30 -> -9.2766029 | E38: =-(E20-D20)*Assumptions!$B$30 -> -9.6940501 | F38: =-(F20-E20)*Assumptions!$B$30 -> -10.130282 | G38: =-(G20-F20)*Assumptions!$B$30 -> -10.586145
A39: Free cash flow before debt repayment | C39: =SUM(C34:C38) -> 420.81084 | D39: =SUM(D34:D38) -> 480.28299 | E39: =SUM(E34:E38) -> 544.89596 | F39: =SUM(F34:F38) -> 615.03092 | G39: =SUM(G34:G38) -> 691.09533
A40: Mandatory TLB amortization | C40: =MIN(Assumptions!$B$20*$B$4,B46) -> 30.90378 | D40: =MIN(Assumptions!$B$20*$B$4,C46) -> 30.90378 | E40: =MIN(Assumptions!$B$20*$B$4,D46) -> 30.90378 | F40: =MIN(Assumptions!$B$20*$B$4,E46) -> 30.90378 | G40: =MIN(Assumptions!$B$20*$B$4,F46) -> 30.90378
A41: Optional TLB paydown (cash sweep) | C41: =MIN(B46-C40,MAX(0,C39-C40)*Assumptions!$B$21) -> 389.90706 | D41: =MIN(C46-D40,MAX(0,D39-D40)*Assumptions!$B$21) -> 449.37921 | E41: =MIN(D46-E40,MAX(0,E39-E40)*Assumptions!$B$21) -> 513.99218 | F41: =MIN(E46-F40,MAX(0,F39-F40)*Assumptions!$B$21) -> 584.12714 | G41: =MIN(F46-G40,MAX(0,G39-G40)*Assumptions!$B$21) -> 660.19155
A42: Net change in cash | C42: =C39-C40-C41 -> 0 | D42: =D39-D40-D41 -> 0 | E42: =E39-E40-E41 -> 0 | F42: =F39-F40-F41 -> 0 | G42: =G39-G40-G41 -> 0
A44: Debt schedule & credit stats | B44: FY2026PF | C44: FY2027E | D44: FY2028E | E44: FY2029E | F44: FY2030E | G44: FY2031E
A45: Term Loan B
A46: Term Loan B (ending) | B46: =B4 -> 3090.378 | C46: =B46-C40-C41 -> 2669.5672 | D46: =C46-D40-D41 -> 2189.2842 | E46: =D46-E40-E41 -> 1644.3882 | F46: =E46-F40-F41 -> 1029.3573 | G46: =F46-G40-G41 -> 338.26195
...

Sheet Sensitivities
A1: Sensitivity analysis (Base case; values computed by a Python replica of the model, verified to match the live model at base inputs)
A3: IRR: entry multiple vs exit multiple (5.0x leverage)
A4: Entry \ Exit | B4: 7.0x | C4: 7.5x | D4: 8.0x | E4: 8.5x | F4: 9.0x
A5: 7.0x | B5: 0.21526483 | C5: 0.23711768 | D5: 0.25752738 | E5: 0.27669214 | F5: 0.29477078
A6: 7.5x | B6: 0.17149729 | C6: 0.19256312 | D6: 0.21223777 | E6: 0.23071231 | F6: 0.24813986
A7: 8.0x | B7: 0.13575665 | C7: 0.15617978 | D7: 0.17525419 | E7: 0.1931651 | F7: 0.21006096
A8: 8.5x | B8: 0.10569908 | C8: 0.12558172 | D8: 0.14415133 | E8: 0.16158823 | F8: 0.17803694
A9: 9.0x | B9: 0.079860391 | C9: 0.099278403 | D9: 0.11741406 | E9: 0.13444349 | F9: 0.15050782
A11: MOIC: entry multiple vs exit multiple (5.0x leverage)
A12: Entry \ Exit | B12: 7.0x | C12: 7.5x | D12: 8.0x | E12: 8.5x | F12: 9.0x
A13: 7.0x | B13: 2.6506638 | C13: 2.897711 | D13: 3.1447581 | E13: 3.3918053 | F13: 3.6388525
A14: 7.5x | B14: 2.2065128 | C14: 2.4121642 | D14: 2.6178156 | E14: 2.8234671 | F14: 3.0291185
A15: 8.0x | B15: 1.8898461 | C15: 2.0659835 | D15: 2.242121 | E15: 2.4182584 | F15: 2.5943959
A16: 8.5x | B16: 1.6526646 | C16: 1.8066963 | D16: 1.960728 | E16: 2.1147596 | F16: 2.2687913
A17: 9.0x | B17: 1.4683786 | C17: 1.6052345 | D17: 1.7420903 | E17: 1.8789461 | F17: 2.015802
A19: IRR: leverage vs entry multiple (8.0x exit)
A20: Leverage \ Entry | B20: 7.0x | C20: 7.5x | D20: 8.0x | E20: 8.5x | F20: 9.0x
A21: 4.0x | B21: 0.21694227 | C21: 0.18439621 | D21: 0.15646092 | E21: 0.13206453 | F21: 0.11046316
A22: 4.5x | B22: 0.23459963 | C22: 0.19670558 | D22: 0.16486875 | E22: 0.13752128 | F22: 0.11362386
A23: 5.0x | B23: 0.25752738 | C23: 0.21223777 | D23: 0.17525419 | E23: 0.14415133 | F23: 0.11741406
A24: 5.5x | B24: 0.2886531 | C24: 0.23249696 | D24: 0.18842243 | E24: 0.15238248 | F24: 0.12204335
A25: 6.0x | B25: 0.3337445 | C25: 0.26013984 | D25: 0.20569557 | E25: 0.16288194 | F25: 0.12782641
A27: Scenario comparison
A28: Metric | B28: Base | C28: Downside
A29: Exit EBITDA (FY2031, $mm) | B29: 1283.2525 | C29: 995.00009
A30: Exit multiple | B30: 8 | C30: 6.5
A31: MOIC | B31: 2.242121 | C31: 0.97577003
A32: IRR | B32: 0.17525419 | C32: -0.0048936556
A33: Total debt / EBITDA at exit | B33: 1.8690896 | C33: 3.2291511
A34: Minimum EBITDA / interest | B34: 2.4293392 | C34: 2.2040367
A36: Downside: revenue growth 0-2%, EBITDA margin falls from 26.1% to 23.5-24.5%, exit multiple 6.5x (vs 8.0x base).

Sheet Source Data
A1: HRB historicals ($mm) | B1: FY2023 | C1: FY2024 | D1: FY2025 | E1: FY2026
A2: Revenue | B2: 3472.185 | C2: 3610.347 | D2: 3760.995 | E2: 3945.392
A3: Adj. EBITDA | B3: 914.691 | C3: 963.186 | D3: 976.343 | E3: 1030.126
A4: Adj. EBITDA margin | B4: 0.263 | C4: 0.267 | D4: 0.26 | E4: 0.261
A5: Operating profit (EBIT) | B5: 748.698 | C5: 805.277 | D5: 827.97 | E5: 907.686
A6: Operating cash flow | B6: 821.841 | C6: 720.86 | D6: 680.883 | E6: 838.695
A7: Capex | B7: 69.698 | C7: 63.678 | D7: 82.034 | E7: 82.614
A8: Net income | B8: 561.8 | C8: 597.963 | D8: 609.45 | E8: 736.318
A11: Market data (Oct 9, 2026): price $44.05; market cap $5,583.8mm; FY2026 total debt $1,491.5mm; cash $958.7mm; 52-week range $28.16 - $58.67.
A12: Source: Perplexity finance data (company financials, adjusted metrics, quotes). Illustrative academic exercise, not investment advice.
